Workbook
Name _BunkersTypes: OFFSET(#REF!,0,0,COUNTA(#REF!))
Name _BunkersUnits: OFFSET(#REF!,0,0,COUNTA(#REF!))
Name _CertificateIssuers: OFFSET(#REF!,0,0,COUNTA(#REF!))
Name _Countries: OFFSET(#REF!,0,0,COUNTA(#REF!))
Name _CrewIdTypes: OFFSET(#REF!,0,0,COUNTA(#REF!))
Name _DgClassifications: OFFSET(#REF!,0,0,COUNTA(#REF!))
Name _DpgUnits: OFFSET(#REF!,0,0,COUNTA(#REF!))
Name _Genders: OFFSET(#REF!,0,0,COUNTA(#REF!))
Name _ImoHazardClasses: OFFSET(#REF!,0,0,COUNTA(#REF!))
Name _IsscIssuerTypes: OFFSET(#REF!,0,0,COUNTA(#REF!))
Name _IsscTypes: OFFSET(#REF!,0,0,COUNTA(#REF!))
Name _LatitudeDirections: #REF!
Name _LongitudeDirections: #REF!
Name _PaxIdTypes: OFFSET(#REF!,0,0,COUNTA(#REF!))
Name _Purposes: OFFSET(#REF!,0,0,COUNTA(#REF!))
Name _SecurityLevels: OFFSET(#REF!,0,0,COUNTA(#REF!))
Name _ShipContactPreferredMediums: OFFSET(#REF!,0,0,COUNTA(#REF!))
Name _ShipStoreTypes: OFFSET(#REF!,0,0,COUNTA(#REF!))
Name _WasteCodes: OFFSET(#REF!,0,0,COUNTA(#REF!))
Name _WasteStatuses: OFFSET(#REF!,0,0,COUNTA(#REF!))
Name _WasteTypes: OFFSET(#REF!,0,0,COUNTA(#REF!))
Name _YesNo: OFFSET(#REF!,0,0,COUNTA(#REF!))
Name Check1: #REF!
Name Check1: #REF!
Name Check1: #REF!
Name Check1: #REF!
Name Check3: #REF!
Name Check3: #REF!
Name Check4: #REF!
Name Check4: #REF!
Name ETA_PortOfCall: #REF!
Name ETD_LastPort: #REF!
Name ETD_PortOfCall: #REF!

Sheet Input
B2: Name: | D2: HANNA | F2: Call Sign: | H2: 5BGV2 | K2: Present Crew Details
B4: Nationality: | D4: Cyprus | F4: Homeport: | H4: Limassol | K4: No. | L4: Family Name, Given Names | M4: Rank | N4: Nationality | P4: Date and Place of Birth | S4: Passport | T4: Seaman's Book | U4: Passport's Validity | V4: S/book's Validity | W4: Cyprus Seaman's Book | X4: Validity | Y4: Visa | Z4: Validity | AA4: Joining Date | AB4: Joining Port
B6: IMO No: | D6: 9376048 | F6: Type: | H6: Container | K6: 1 | L6: ZHYKHARIEV, Dmytro | M6: Master | N6: Ukraine | P6: 31731 | Q6: Ukraine, Kherson | S6: FH557277 | T6: AB662852 | U6: 18.08.2017-18.08.2027 | V6: 05.06.2020-05.06.2030 | W6: CY340880 | X6: 21.02.2022-20.02.2032 | Y6: BIOMETRIC | AA6: 46130 | AB6: FRMRS
K7: 2 | L7: LAURENTE, Artemio Belza | M7: Ch.Off | N7: Philippines | P7: 31920 | Q7: Barugo, Leyte | S7: P3901669B | T7: C1564756 | U7: 20.11.2019-19.11.2029 | V7: 02.12.2019-02.12.2029 | W7: CY367312 | X7: 24.07.2023-23.07.2033 | AA7: 46153 | AB7: FRMRS
B8: Date of Arrival: | D8: 46167 | K8: 3 | L8: MAKAR, Maksym | M8: 2nd Off | N8: Ukraine | P8: 33186 | Q8: Ukraine, Odessa | S8: FK832567 | T8: AC004954 | U8: 12.01.2018-12.01.2028 | V8: 07.10.2022-07.10.2027 | W8: Application | Y8: BIOMETRIC | AA8: 46068 | AB8: FRMRS
K9: 4 | L9: ZADOROZHNY, Sergiy | M9: Ch.Eng | N9: Ukraine | P9: 21788 | Q9: Ukraine, Odessa | S9: FU050737 | T9: AB640625 | U9: 05.02.2019-05.02.2029 | V9: 29.07.2019-21.11.2028 | Y9: BIOMETRIC | AA9: 46153 | AB9: FRMRS
B10: Date of Departure: | D10: 46168 | K10: 5 | L10: HONCHAR, Yurii | M10: 2nd Eng | N10: Ukraine | P10: 31151 | Q10: Ukraine | S10: GJ014077 | T10: AB630373 | U10: 25.03.2024-25.03.2034 | V10: 20.06.2018-30.11.2027 | W10: Application | Y10: BIOMETRIC | AA10: 46059 | AB10: DZBJA
K11: 6 | L11: CORCINO, Renand Aparece | M11: A/B | N11: Philippines | P11: 33807 | Q11: Inabanga, Bohol | S11: P3970180B | T11: C1547533 | U11: 26.11.2019-25.11.2029 | V11: 05.12.2019-02.12.2029 | W11: CY383140 | X11: 25.07.2024-24.07.2034 | Y11: FRA 612575209 | Z11: 06.02.2026-05.02.2029 | AA11: 46069 | AB11: FRMRS
B12: Port of Call: | D12: Napoli | G12: Alger | K12: 7 | L12: BANEZ, John Kenneth Rebundas | M12: O/S | N12: Philippines | P12: 36429 | Q12: Malolos, Bulacan | S12: P1370110C | T12: A0195751 | U12: 18.08.2022-17.08.2032 | V12: 20.06.2022-20.06.2032 | W12: CY385020 | X12: 07.08.2024-06.08.2034 | Y12: FRA 612557957 | Z12: 17.07.2025-16.07.2026 | AA12: 45886 | AB12: FRLEH
G13: Napoli | K13: 8 | L13: PERNIA, James Malitao | M13: O/S | N13: Philippines | P13: 36100 | Q13: Buenavista, Marinduque | S13: P7743571B | T13: C1332465 | U13: 01.10.2021-30.09.2031 | V13: 20.08.2018-17.08.2028 | W13: CY388194 | X13: 20.11.2024-19.11.2024 | Y13: FRA 612577136 | Z13: 05.02.2026-04.08.2026 | AA13: 46068 | AB13: FRMRS
B14: Last Port of Call: | D14: Alger | G14: Salerno | K14: 9 | L14: CANTOS, Philip Justin Perez | M14: O/S | N14: Philippines | P14: 36743 | Q14: Batangas City | S14: P5075641C | T14: A0011575 | U14: 24.08.2023-23.08.2033 | V14: 11.08.2021-11.08.2031 | W14: Application | Y14: FRA 612577137 | Z14: 05.02.2026-04.02.2027 | AA14: 46068 | AB14: FRMRS
G15: La Spezia | K15: 10 | L15: ROMULO, Roland Bong Rosal | M15: O/S | N15: Philippines | P15: 36517 | Q15: Manila | S15: P7652618B | T15: A0177653 | U15: 21.09.2021-20.09.2031 | V15: 06.01.2022-06.01.2032 | W15: CY385721 | X15: 17.09.2024-16.09.2034 | Y15: FRA 612567464 | Z15: 08.11.2025-07.11.2027 | AA15: 46068 | AB15: BEANR
B16: Next Port of Call: | D16: La Spezia | G16: Genoa | K16: 11 | L16: MATALUBOS, Gerald Maniapao | M16: Wiper | N16: Philippines | P16: 36614 | Q16: Navotas, Metro Manila | S16: P0009456C | T16: A0154698 | U16: 11.05.2022-10.05.2032 | V16: 28.03.2022-28.03.2032 | W16: Application | AA16: 46033 | AB16: DZALG
G17: Marseille | K17: 12 | L17: BERNABE, Brian Malaluan | M17: Cook | N17: Philippines | P17: 31894 | Q17: Koronadal So. Cot. | S17: P8802413B | T17: C1254434 | U17: 28.01.2022-27.01.2032 | V17: 23.05.2018-20.05.2028 | W17: Application | Y17: ESP 023817584 | Z17: 01.12.2024-30.11.2026 | AA17: 46063 | AB17: ITSPE
B18: Charterer: | D18: CMA CGM | K18: 13 | L18: SISON, Jan Randell Rollo | M18: Dcad | N18: Philippines | P18: 37407 | Q18: Alaminos City | S18: P5175257C | T18: A0322770 | U18: 06.09.2023-05.09.2033 | V18: 08.08.2024-08.08.2034 | W18: Application | Y18: FRA 612567161 | Z18: 03.11.2025-02.05.2026 | AA18: 46153 | AB18: FRMRS
K21: Previous Crew Details
K22: No. | L22: Family Name, Given Names | M22: Rank | N22: Nationality | P22: Date and Place of Birth | S22: Passport | T22: Seaman's Book | U22: Passport's Validity | V22: S/book's Validity | W22: Cyprus Seaman's Book | X22: Validity | Y22: Visa | Z22: Validity | AA22: Joining Date | AB22: Joining Port
L23: SOKOLOV, Pavel | M23: Master | N23: Russian Federation | P23: 26768 | Q23: USSR, Kaluga Reg. | S23: 776406535 | T23: MK 0158687 | U23: 03.06.2025-03.06.2035 | V23: 04.04.2013 - Unlimited | W23: CY266502 | X23: 26.04.2017-25.04.2027 | Y23: NLD 018831776 | Z23: 23.07.2025-22.07.2026 | AA23: 45894 | AB23: FRLEH
L24: UGROVATOV, Andrey | M24: Master | N24: Russian Federation | P24: 19.03.76 | Q24: USSR, Rostov-on-Don | S24: 763732667 | T24: MK 0135153 | U24: 17.12.2020-17.12.2030 | V24: 07.09.2012 - Unlimited | W24: CY339478 | X24: 14.02.2022-13.02.2032 | Y24: NLD 018439401 | Z24: 02.04.2025-01.04.2026 | AA24: 46006 | AB24: DZALG
L25: ZHYKHARIEV, Dmytro | M25: Master | N25: Ukraine | P25: 31731 | Q25: Ukraine, Kherson | S25: FH557277 | T25: AB662852 | U25: 18.08.2017-18.08.2027 | V25: 05.06.2020-05.06.2030 | W25: CY340880 | X25: 21.02.2022-20.02.2032 | Y25: BIOMETRIC | AA25: 45886 | AB25: FRLEH
L26: ZELENKOV, Artur | M26: Ch.Off | N26: Russian Federation | P26: 15.01.89 | Q26: USSR, Kherson | S26: 773335811 | T26: MK0198564 | U26: 03.05.2024-03.05.2034 | V26: 27.02.2017-Unlimited | W26: CY306847 | X26: 06.08.2019-05.08.2029 | Y26: BIOMETRIC | AA26: 45997 | AB26: FRMRS
L27: LAURENTE, Artemio Belza | M27: Ch.Off | N27: Philippines | P27: 31920 | Q27: Barugo, Leyte | S27: P3901669B | T27: C1564756 | U27: 20.11.2019-19.11.2029 | V27: 02.12.2019-02.12.2029 | W27: CY367312 | X27: 24.07.2023-23.07.2033 | Y27: FRA 607959577 | Z27: 10.04.2024-09.04.2026 | AA27: 46005 | AB27: DZALG
L28: MAKAR, Maksym | M28: 2nd Off | N28: Ukraine | P28: 33186 | Q28: Ukraine, Odessa | S28: FK832567 | T28: AC004954 | U28: 12.01.2018-12.01.2028 | V28: 07.10.2022-07.10.2027 | W28: Application | Y28: BIOMETRIC | AA28: 46069 | AB28: FRMRS
L29: ZADOROZHNY, Sergiy | M29: Ch.Eng | N29: Ukraine | P29: 21788 | Q29: Ukraine, Odessa | S29: FU050737 | T29: AB640625 | U29: 05.02.2019-05.02.2029 | V29: 29.07.2019-21.11.2028 | W29: CY249054 | X29: 07.01.2016-06.01.2026 | Y29: BIOMETRIC | AA29: 45871 | AB29: FRLEH
L30: PANIROVSKIY, Maxim | M30: Ch.Eng | N30: Russian Federation | P30: 25921 | Q30: USSR, Alma-Ata | S30: 760554340 | T30: MK0126676 | U30: 25.04.2019-25.04.2029 | V30: 05.08.2011-Unlimited | W30: CY324861 | X30: 23.12.2020-22.12.2030 | Y30: NLD 017905326 | Z30: 07.06.2024-07.06.2025
L31: CHERVIAK, Oleksandr | M31: Ch.Eng | N31: Ukraine | P31: 22.08.92 | Q31: Ukraine, Ternopil | S31: FH202954 | T31: AB631580 | U31: 27.07.2017-27.07.2027 | V31: 18.09.2018-13.09.2028 | W31: CY387300 | X31: 31.10.2024-30.10.2034 | Y31: BIOMETRIC | AA31: 46006 | AB31: DZALG
L32: KHARNIKOV, Vadim | M32: 2nd Eng | N32: Russian Federation | P32: 10.10.61 | Q32: USSR, Kaliningrad | S32: 771749004 | T32: MK 0137378 | U32: 02.11.2023-02.11.2033 | V32: 09.08.2012-Unlimited | W32: CY354917 | X32: 23.01.2023-22.01.2033 | Y32: NLD018309238 | Z32: 16.11.2024-16.11.2025 | AA32: 45886 | AB32: FRLEH
L33: HONCHAR, Yurii | M33: 2nd Eng | N33: Ukraine | P33: 31151 | Q33: Ukraine | S33: GJ014077 | T33: AB630373 | U33: 25.03.2024-25.03.2034 | V33: 20.06.2018-30.11.2027 | W33: Application | Y33: BIOMETRIC | AA33: 46059 | AB33: DZBJA
L34: SOBERE, Edmond Dequilla | M34: A/B | N34: Philippines | P34: 03.11.90 | Q34: Pasig City | S34: P0606328B | T34: C1430561 | U34: 09.02.2019-08.02.2029 | V34: 04.02.2019-01.02.2029
L35: ROQUID, Van Cloyd Blanco | M35: A/B | N35: Philippines | P35: 25.10.87 | Q35: CARMEN, DAVAO | S35: P9969761A | T35: A0055405 | U35: 18.12.2018-17.12.2028 | V35: 21.05.2020-21.05.2030
L36: CORONEL, Garileo Tadeo | M36: A/B | N36: Philippines | P36: 10.08.77 | Q36: Bustos, Bulacan | S36: P1296721B | T36: C0939777 | U36: 01.04.2019-31.03.2029 | V36: 26.10.2016-24.10.2026
L37: LAS, Marvicrizer Ramos | M37: A/B | N37: Philippines | P37: 06.08.90 | Q37: MAPUN TAWI TAWI | S37: P5969089B | T37: C1163645 | U37: 17.12.2020-16.12.2030 | V37: 18.10.2017-16.10.2027
L38: LUMANSOC, Joel | M38: A/B | N38: Philippines | P38: 03.12.78 | Q38: Tagbilaran City | S38: EC7692031 | T38: C0439098 | U38: 12.05.2016-11.05.2021 | V38: 12.05.2015-10.05.2020
L39: ALAGENIO, Rolly Clamonte | M39: A/B | N39: Philippines | P39: 21.01.86 | Q39: Dumalinao, Zamboanga Del Sur | S39: P6705982B | T39: C0728453 | U39: 27.04.2021-26.04.2031 | V39: 26.01.2017-24.01.2027
L40: MELMIDA, Anselmo Pasaylo | M40: A/B | N40: Philippines | P40: 24.05.69 | Q40: Lala Lanao Dn | S40: P7750883A | T40: C1528930 | U40: 30.06.2018-29.06.2028 | V40: 27.09.2019-24.09.2029
L41: SOMBLINGO, Wilson Ian Ventura | M41: A/B | N41: Philippines | P41: 21.03.87 | Q41: BACOLOD CITY | S41: P5636365B | T41: C1065326 | U41: 14.10.2020-13.10.2025 | V41: 04.07.2017-02.07.2027
L42: PADUA, Efren Jay Amigable | M42: A/B | N42: Philippines | P42: 17.10.89 | Q42: GUIUAN EASTERN SAMAR | S42: P6954831A | T42: C1053742 | U42: 27.04.2018-26.04.2028 | V42: 07.05.2018-04.05.2028
L43: SAMULDE, Samuel Jr. Ignacio | M43: A/B | N43: Philippines | P43: 30.11.93 | Q43: Taguig MM | S43: P7070657B | T43: C1069798 | U43: 30.06.2021-29.06.2031 | V43: 14.08.2017-12.08.2027
L44: GULLAS, James Villapana | M44: A/B | N44: Philippines | P44: 33264 | Q44: San Agustin, SDS | S44: P5732609B | T44: C1069798 | U44: 30.06.2021-29.06.2031 | V44: 14.08.2017-12.08.2027
L45: GRANJA, John Ryan Eumenda | M45: A/B | N45: Philippines | P45: 06.09.94 | Q45: Bacolod City | S45: P4850471B | T45: C1412230 | U45: 18.02.2020-17.02.2030 | V45: 06.11.2018-03.11.2028 | W45: CY303693 | X45: 10.05.2019-09.05.2029 | Y45: D 067597859 | Z45: 29.01.2023-28.01.2027
...

Sheet Port of Call List
A2: Port of Call List
A4: 1.Name of Ship | C4: Call Sign | E4: 2.Port of Arrival | F4: 3.Date of Arrival
A5: =Input!D2 -> HANNA | C5: =Input!H2 -> 5BGV2 | E5: =Input!D12 -> Napoli | F5: =Input!D8 -> 46167
A6: 4.Nationality of Ship | C6: 5. Homeport | D6: 6.Port arrived from | F6: 7.Sailing to
A7: =Input!D4 -> Cyprus | C7: =Input!H4 -> Limassol | D7: =Input!D14 -> Alger | F7: =Input!D16 -> La Spezia
A8: 8. Voy. No. | B8: 9. Last Port of Call | C8: 10. Country | D8: 11.Date of Arrival | E8: 12. Time of arrival | F8: 13.Date of Departure | G8: 14. Time of Departure
E9: Local Time | G9: Local Time
A10: 1 | B10: ALGER | C10: ALGERIA | D10: 46161 | E10: 02:00 | F10: 46166 | G10: 09:00 | H10: DZALG
A11: 2 | B11: MARSEILLE | C11: FRANCE | D11: 46153 | E11: 02:30 | F11: 46154 | G11: 21:18 | H11: FRMRS
A12: 3 | B12: LA SPEZIA | C12: ITALY | D12: 46151 | E12: 17:54 | F12: 46152 | G12: 05:48 | H12: ITSPE
A13: 4 | B13: GENOA | C13: ITALY | D13: 46150 | E13: 20:36 | F13: 46151 | G13: 12:00 | H13: ITGOA
A14: 5 | B14: SALERNO | C14: ITALY | D14: 46149 | E14: 08:48 | F14: 46149 | G14: 22:00 | H14: ITSAL
A15: 6 | B15: NAPOLI | C15: ITALY | D15: 46144 | E15: 07:00 | F15: 46144 | G15: 21:06 | H15: ITNAP
A16: 7 | B16: ALGER | C16: ALGERIA | D16: 46136 | E16: 08:24 | F16: 46140 | G16: 21:24 | H16: DZALG
A17: 8 | B17: MARSEILLE | C17: FRANCE | D17: 46130 | E17: 20:48 | F17: 46133 | G17: 18:24 | H17: FRMRS
A18: 9 | B18: GENOA | C18: ITALY | D18: 46129 | E18: 13:06 | F18: 46129 | G18: 21:06 | H18: ITGOA
A19: 10 | B19: LA SPEZIA | C19: ITALY | D19: 46126 | E19: 17:00 | F19: 46129 | G19: 04:30 | H19: ITSPE
C30: 15. Date and signature by master, authorised agent or officer

Sheet ISPS (POC Company Form)
H2: IMO No. 9 3 7 6 0 4 8 | O2: Security Form 3
H3: CALL SIGN: 5 B G V 2 | O3: Last 10 Ports of Call
B4: Last 10 Ports of Call
M5: Port of Call: | O5: =Input!D12 -> Napoli
B6: Vessel Name: | E6: mv HANNA | M6: Arrival Date: | O6: =Input!D8 -> 46167
B7: Nationality of Ship: | E7: Cyprus | M7: Last Port: | O7: =Input!D14 -> Alger
B8: Port of Registry: | E8: Limmasol | M8: Next Port: | O8: =Input!D16 -> La Spezia
B10: IMO Port Facility Number * | F10: Arrival | H10: Departure | J10: Security Level / Change of Level | O10: DOS signed | Q10: Additional Temporary Security Measures
B11: or alternatively
B12: Country, Port, Facility | F12: date | G12: time | H12: date | I12: time | J12: ship | K12: shore | L12: to | M12: date | N12: time | O12: yes | P12: no | Q12: (if applicable)
B13: ='Port of Call List'!A10 -> 1 | C13: ='Port of Call List'!B10 -> ALGER | D13: ='Port of Call List'!C10 -> ALGERIA | E13: ='Port of Call List'!H10 -> DZALG | F13: ='Port of Call List'!D10 -> 46161 | G13: ='Port of Call List'!E10 -> 02:00 | H13: ='Port of Call List'!F10 -> 46166 | I13: ='Port of Call List'!G10 -> 09:00 | J13: 1 | K13: 1 | L13: - | M13: n/a | N13: n/a | O13: x | P13: - | Q13: gangway watch maintaned, safety and security patrol carried out frequently
B14: ='Port of Call List'!A11 -> 2 | C14: ='Port of Call List'!B11 -> MARSEILLE | D14: ='Port of Call List'!C11 -> FRANCE | E14: ='Port of Call List'!H11 -> FRMRS | F14: ='Port of Call List'!D11 -> 46153 | G14: ='Port of Call List'!E11 -> 02:30 | H14: ='Port of Call List'!F11 -> 46154 | I14: ='Port of Call List'!G11 -> 21:18 | J14: 1 | K14: 1 | L14: - | M14: n/a | N14: n/a | O14: x | P14: - | Q14: gangway watch maintaned, safety and security patrol carried out frequently
B15: ='Port of Call List'!A12 -> 3 | C15: ='Port of Call List'!B12 -> LA SPEZIA | D15: ='Port of Call List'!C12 -> ITALY | E15: ='Port of Call List'!H12 -> ITSPE | F15: ='Port of Call List'!D12 -> 46151 | G15: ='Port of Call List'!E12 -> 17:54 | H15: ='Port of Call List'!F12 -> 46152 | I15: ='Port of Call List'!G12 -> 05:48 | J15: 1 | K15: 1 | L15: - | M15: n/a | N15: n/a | O15: x | P15: - | Q15: gangway watch maintaned, safety and security patrol carried out frequently
B16: ='Port of Call List'!A13 -> 4 | C16: ='Port of Call List'!B13 -> GENOA | D16: ='Port of Call List'!C13 -> ITALY | E16: ='Port of Call List'!H13 -> ITGOA | F16: ='Port of Call List'!D13 -> 46150 | G16: ='Port of Call List'!E13 -> 20:36 | H16: ='Port of Call List'!F13 -> 46151 | I16: ='Port of Call List'!G13 -> 12:00 | J16: 1 | K16: 1 | L16: - | M16: n/a | N16: n/a | O16: x | P16: - | Q16: gangway watch maintaned, safety and security patrol carried out frequently
B17: ='Port of Call List'!A14 -> 5 | C17: ='Port of Call List'!B14 -> SALERNO | D17: ='Port of Call List'!C14 -> ITALY | E17: ='Port of Call List'!H14 -> ITSAL | F17: ='Port of Call List'!D14 -> 46149 | G17: ='Port of Call List'!E14 -> 08:48 | H17: ='Port of Call List'!F14 -> 46149 | I17: ='Port of Call List'!G14 -> 22:00 | J17: 1 | K17: 1 | L17: - | M17: n/a | N17: n/a | O17: x | P17: - | Q17: gangway watch maintaned, safety and security patrol carried out frequently
B18: ='Port of Call List'!A15 -> 6 | C18: ='Port of Call List'!B15 -> NAPOLI | D18: ='Port of Call List'!C15 -> ITALY | E18: ='Port of Call List'!H15 -> ITNAP | F18: ='Port of Call List'!D15 -> 46144 | G18: ='Port of Call List'!E15 -> 07:00 | H18: ='Port of Call List'!F15 -> 46144 | I18: ='Port of Call List'!G15 -> 21:06 | J18: 1 | K18: 1 | L18: - | M18: n/a | N18: n/a | O18: x | P18: - | Q18: gangway watch maintaned, safety and security patrol carried out frequently
B19: ='Port of Call List'!A16 -> 7 | C19: ='Port of Call List'!B16 -> ALGER | D19: ='Port of Call List'!C16 -> ALGERIA | E19: ='Port of Call List'!H16 -> DZALG | F19: ='Port of Call List'!D16 -> 46136 | G19: ='Port of Call List'!E16 -> 08:24 | H19: ='Port of Call List'!F16 -> 46140 | I19: ='Port of Call List'!G16 -> 21:24 | J19: 1 | K19: 1 | L19: - | M19: n/a | N19: n/a | O19: x | P19: - | Q19: gangway watch maintaned, safety and security patrol carried out frequently
B20: ='Port of Call List'!A17 -> 8 | C20: ='Port of Call List'!B17 -> MARSEILLE | D20: ='Port of Call List'!C17 -> FRANCE | E20: ='Port of Call List'!H17 -> FRMRS | F20: ='Port of Call List'!D17 -> 46130 | G20: ='Port of Call List'!E17 -> 20:48 | H20: ='Port of Call List'!F17 -> 46133 | I20: ='Port of Call List'!G17 -> 18:24 | J20: 1 | K20: 1 | L20: - | M20: n/a | N20: n/a | O20: x | P20: - | Q20: gangway watch maintaned, safety and security patrol carried out frequently
B21: ='Port of Call List'!A18 -> 9 | C21: ='Port of Call List'!B18 -> GENOA | D21: ='Port of Call List'!C18 -> ITALY | E21: ='Port of Call List'!H18 -> ITGOA | F21: ='Port of Call List'!D18 -> 46129 | G21: ='Port of Call List'!E18 -> 13:06 | H21: ='Port of Call List'!F18 -> 46129 | I21: ='Port of Call List'!G18 -> 21:06 | J21: 1 | K21: 1 | L21: - | M21: n/a | N21: n/a | O21: x | P21: - | Q21: gangway watch maintaned, safety and security patrol carried out frequently
B22: ='Port of Call List'!A19 -> 10 | C22: ='Port of Call List'!B19 -> LA SPEZIA | D22: ='Port of Call List'!C19 -> ITALY | E22: ='Port of Call List'!H19 -> ITSPE | F22: ='Port of Call List'!D19 -> 46126 | G22: ='Port of Call List'!E19 -> 17:00 | H22: ='Port of Call List'!F19 -> 46129 | I22: ='Port of Call List'!G19 -> 04:30 | J22: 1 | K22: 1 | L22: - | M22: n/a | N22: n/a | O22: x | P22: - | Q22: gangway watch maintaned, safety and security patrol carried out frequently
B24: Pre Arrival Notifications are required to be kept on board for at least the last 10 ports of call (or 90 days, whichever is the longer period). Such list can be kept in an electronic way for faster exchange with port authorities.
B26: * Port Facility Numbers are to be found on attached CD-ROM | Q26: sign and stamp
M27: Master: | O27: =Input!L6 -> ZHYKHARIEV, Dmytro
B28: Revision | G28: Checked by | K28: Date effective | O28: Page
B29: 0 | G29: CSO | K29: 42804 | O29: 1 of 1

Sheet Crew Arr.
B1: IMO CREW LIST
J3: Page No.
E4: x | F4: Arrival | I4: Departure | J4: 1
B5: 1. Name of ship | E5: 2. Port of arrival / departure | H5: 3. Date of arrival / departure
B6: =Input!D2 -> HANNA | E6: =Input!D12 -> Napoli | H6: =Input!D8 -> 46167
B7: 4. Nationality of Ship | E7: 5. Port arrived from / Sailing to | J7: 6. Nature und No. of identity documents
B8: =Input!D4 -> Cyprus | E8: =Input!D14 -> Alger | H8: / | I8: =Input!D16 -> La Spezia
B9: 7. No. | C9: 8. Family names, given names | D9: 9. Rank or rating | E9: 10. Nationality | G9: 11. Date and place of birth
J10: Passport
A11: IMO Convention on Facilitation of International Maritime Traffic | B11: =Input!K6 -> 1 | C11: =+Input!L6 -> ZHYKHARIEV, Dmytro | D11: =Input!M6 -> Master | E11: =Input!N6 -> Ukraine | G11: =+Input!P6 -> 31731 | H11: =+Input!Q6 -> Ukraine, Kherson | J11: =Input!S6 -> FH557277
B12: =Input!K7 -> 2 | C12: =Input!L7 -> LAURENTE, Artemio Belza | D12: =Input!M7 -> Ch.Off | E12: =Input!N7 -> Philippines | G12: =Input!P7 -> 31920 | H12: =Input!Q7 -> Barugo, Leyte | J12: =Input!S7 -> P3901669B
B13: =Input!K8 -> 3 | C13: =Input!L8 -> MAKAR, Maksym | D13: =Input!M8 -> 2nd Off | E13: =Input!N8 -> Ukraine | G13: =Input!P8 -> 33186 | H13: =Input!Q8 -> Ukraine, Odessa | J13: =Input!S8 -> FK832567
B14: =Input!K9 -> 4 | C14: =Input!L9 -> ZADOROZHNY, Sergiy | D14: =Input!M9 -> Ch.Eng | E14: =Input!N9 -> Ukraine | G14: =Input!P9 -> 21788 | H14: =Input!Q9 -> Ukraine, Odessa | J14: =Input!S9 -> FU050737
B15: =Input!K10 -> 5 | C15: =Input!L10 -> HONCHAR, Yurii | D15: =Input!M10 -> 2nd Eng | E15: =Input!N10 -> Ukraine | G15: =Input!P10 -> 31151 | H15: =Input!Q10 -> Ukraine | J15: =Input!S10 -> GJ014077
B16: =Input!K11 -> 6 | C16: =Input!L11 -> CORCINO, Renand Aparece | D16: =Input!M11 -> A/B | E16: =Input!N11 -> Philippines | G16: =Input!P11 -> 33807 | H16: =Input!Q11 -> Inabanga, Bohol | J16: =Input!S11 -> P3970180B
B17: =Input!K12 -> 7 | C17: =Input!L12 -> BANEZ, John Kenneth Rebundas | D17: =Input!M12 -> O/S | E17: =Input!N12 -> Philippines | G17: =Input!P12 -> 36429 | H17: =Input!Q12 -> Malolos, Bulacan | J17: =Input!S12 -> P1370110C
B18: =Input!K13 -> 8 | C18: =Input!L13 -> PERNIA, James Malitao | D18: =Input!M13 -> O/S | E18: =Input!N13 -> Philippines | G18: =Input!P13 -> 36100 | H18: =Input!Q13 -> Buenavista, Marinduque | J18: =Input!S13 -> P7743571B
B19: =Input!K14 -> 9 | C19: =Input!L14 -> CANTOS, Philip Justin Perez | D19: =Input!M14 -> O/S | E19: =Input!N14 -> Philippines | G19: =Input!P14 -> 36743 | H19: =Input!Q14 -> Batangas City | J19: =Input!S14 -> P5075641C
B20: =Input!K15 -> 10 | C20: =Input!L15 -> ROMULO, Roland Bong Rosal | D20: =Input!M15 -> O/S | E20: =Input!N15 -> Philippines | G20: =Input!P15 -> 36517 | H20: =Input!Q15 -> Manila | J20: =Input!S15 -> P7652618B
B21: =Input!K16 -> 11 | C21: =Input!L16 -> MATALUBOS, Gerald Maniapao | D21: =Input!M16 -> Wiper | E21: =Input!N16 -> Philippines | G21: =Input!P16 -> 36614 | H21: =Input!Q16 -> Navotas, Metro Manila | J21: =Input!S16 -> P0009456C
B22: =Input!K17 -> 12 | C22: =Input!L17 -> BERNABE, Brian Malaluan | D22: =Input!M17 -> Cook | E22: =Input!N17 -> Philippines | G22: =Input!P17 -> 31894 | H22: =Input!Q17 -> Koronadal So. Cot. | J22: =Input!S17 -> P8802413B
B23: =Input!K18 -> 13 | C23: =Input!L18 -> SISON, Jan Randell Rollo | D23: =Input!M18 -> Dcad | E23: =Input!N18 -> Philippines | G23: =Input!P18 -> 37407 | H23: =Input!Q18 -> Alaminos City | J23: =Input!S18 -> P5175257C
A34: IMO FAL Form 5
B35: 12. Date and signature by master, authorised agent or officer

Sheet Crew Dep.
B1: IMO CREW LIST
J3: Page No.
F4: Arrival | H4: x | I4: Departure | J4: 1
B5: 1. Name of ship | E5: 2. Port of arrival / departure | H5: 3. Date of arrival / departure
B6: =Input!D2 -> HANNA | E6: =Input!D12 -> Napoli | H6: =Input!D10 -> 46168
B7: 4. Nationality of Ship | E7: 5. Port of destination | J7: 6. Nature und No. of identity documents
B8: =Input!D4 -> Cyprus | E8: =Input!D16 -> La Spezia
B9: 7. No. | C9: 8. Family names, given names | D9: 9. Rank or rating | E9: 10. Nationality | G9: 11. Date and place of birth
J10: Passport
A11: IMO Convention on Facilitation of International Maritime Traffic | B11: =Input!K6 -> 1 | C11: =Input!L6 -> ZHYKHARIEV, Dmytro | D11: =Input!M6 -> Master | E11: =Input!N6 -> Ukraine | G11: =Input!P6 -> 31731 | H11: =Input!Q6 -> Ukraine, Kherson | J11: =Input!S6 -> FH557277
B12: =Input!K7 -> 2 | C12: =Input!L7 -> LAURENTE, Artemio Belza | D12: =Input!M7 -> Ch.Off | E12: =Input!N7 -> Philippines | G12: =Input!P7 -> 31920 | H12: =Input!Q7 -> Barugo, Leyte | J12: =Input!S7 -> P3901669B
B13: =Input!K8 -> 3 | C13: =Input!L8 -> MAKAR, Maksym | D13: =Input!M8 -> 2nd Off | E13: =Input!N8 -> Ukraine | G13: =Input!P8 -> 33186 | H13: =Input!Q8 -> Ukraine, Odessa | J13: =Input!S8 -> FK832567
B14: =Input!K9 -> 4 | C14: =Input!L9 -> ZADOROZHNY, Sergiy | D14: =Input!M9 -> Ch.Eng | E14: =Input!N9 -> Ukraine | G14: =Input!P9 -> 21788 | H14: =Input!Q9 -> Ukraine, Odessa | J14: =Input!S9 -> FU050737
B15: =Input!K10 -> 5 | C15: =Input!L10 -> HONCHAR, Yurii | D15: =Input!M10 -> 2nd Eng | E15: =Input!N10 -> Ukraine | G15: =Input!P10 -> 31151 | H15: =Input!Q10 -> Ukraine | J15: =Input!S10 -> GJ014077
B16: =Input!K11 -> 6 | C16: =Input!L11 -> CORCINO, Renand Aparece | D16: =Input!M11 -> A/B | E16: =Input!N11 -> Philippines | G16: =Input!P11 -> 33807 | H16: =Input!Q11 -> Inabanga, Bohol | J16: =Input!S11 -> P3970180B
B17: =Input!K12 -> 7 | C17: =Input!L12 -> BANEZ, John Kenneth Rebundas | D17: =Input!M12 -> O/S | E17: =Input!N12 -> Philippines | G17: =Input!P12 -> 36429 | H17: =Input!Q12 -> Malolos, Bulacan | J17: =Input!S12 -> P1370110C
B18: =Input!K13 -> 8 | C18: =Input!L13 -> PERNIA, James Malitao | D18: =Input!M13 -> O/S | E18: =Input!N13 -> Philippines | G18: =Input!P13 -> 36100 | H18: =Input!Q13 -> Buenavista, Marinduque | J18: =Input!S13 -> P7743571B
B19: =Input!K14 -> 9 | C19: =Input!L14 -> CANTOS, Philip Justin Perez | D19: =Input!M14 -> O/S | E19: =Input!N14 -> Philippines | G19: =Input!P14 -> 36743 | H19: =Input!Q14 -> Batangas City | J19: =Input!S14 -> P5075641C
B20: =Input!K15 -> 10 | C20: =Input!L15 -> ROMULO, Roland Bong Rosal | D20: =Input!M15 -> O/S | E20: =Input!N15 -> Philippines | G20: =Input!P15 -> 36517 | H20: =Input!Q15 -> Manila | J20: =Input!S15 -> P7652618B
B21: =Input!K16 -> 11 | C21: =Input!L16 -> MATALUBOS, Gerald Maniapao | D21: =Input!M16 -> Wiper | E21: =Input!N16 -> Philippines | G21: =Input!P16 -> 36614 | H21: =Input!Q16 -> Navotas, Metro Manila | J21: =Input!S16 -> P0009456C
B22: =Input!K17 -> 12 | C22: =Input!L17 -> BERNABE, Brian Malaluan | D22: =Input!M17 -> Cook | E22: =Input!N17 -> Philippines | G22: =Input!P17 -> 31894 | H22: =Input!Q17 -> Koronadal So. Cot. | J22: =Input!S17 -> P8802413B
B23: =Input!K18 -> 13 | C23: =Input!L18 -> SISON, Jan Randell Rollo | D23: =Input!M18 -> Dcad | E23: =Input!N18 -> Philippines | G23: =Input!P18 -> 37407 | H23: =Input!Q18 -> Alaminos City | J23: =Input!S18 -> P5175257C
A33: IMO FAL Form 5
B34: 12. Date and signature by master, authorised agent or officer
E43: PT(August 2003)

Sheet Crew Arr. (ALG)
B1: IMO CREW LIST
J3: Page No. | L3: Date of joining the vessel
E4: x | F4: Arrival | I4: Departure | J4: 1 | M4: Place of joining the vessel | N4: Temperature of each crew member
B5: 1. Name of ship | E5: 2. Port of arrival / departure | H5: 3. Date of arrival / departure
B6: =Input!D2 -> HANNA | E6: =Input!D12 -> Napoli | H6: =Input!D8 -> 46167
B7: 4. Nationality of Ship | E7: 5. Port arrived from / Sailing to | J7: 6. Nature und No. of identity documents | K7: 6. Nature und No. of identity documents
B8: =Input!D4 -> Cyprus | E8: =Input!D14 -> Alger | H8: / | I8: =Input!D16 -> La Spezia
B9: 7. No. | C9: 8. Family names, given names | D9: 9. Rank or rating | E9: 10. Nationality | G9: 11. Date and place of birth | K9: Seaman's book
J10: Passport
A11: IMO Convention on Facilitation of International Maritime Traffic | B11: =Input!K6 -> 1 | C11: =+Input!L6 -> ZHYKHARIEV, Dmytro | D11: =Input!M6 -> Master | E11: =Input!N6 -> Ukraine | G11: =+Input!P6 -> 31731 | H11: =+Input!Q6 -> Ukraine, Kherson | J11: =Input!S6 -> FH557277 | K11: =+Input!T6 -> AB662852 | L11: =Input!AA6 -> 46130 | M11: =Input!AB6 -> FRMRS | N11: 36.6 C
B12: =Input!K7 -> 2 | C12: =Input!L7 -> LAURENTE, Artemio Belza | D12: =Input!M7 -> Ch.Off | E12: =Input!N7 -> Philippines | G12: =Input!P7 -> 31920 | H12: =Input!Q7 -> Barugo, Leyte | J12: =Input!S7 -> P3901669B | K12: =+Input!T7 -> C1564756 | L12: =Input!AA7 -> 46153 | M12: =Input!AB7 -> FRMRS | N12: 36.6 C
B13: =Input!K8 -> 3 | C13: =Input!L8 -> MAKAR, Maksym | D13: =Input!M8 -> 2nd Off | E13: =Input!N8 -> Ukraine | G13: =Input!P8 -> 33186 | H13: =Input!Q8 -> Ukraine, Odessa | J13: =Input!S8 -> FK832567 | K13: =+Input!T8 -> AC004954 | L13: =Input!AA8 -> 46068 | M13: =Input!AB8 -> FRMRS | N13: 36.7 C
B14: =Input!K9 -> 4 | C14: =Input!L9 -> ZADOROZHNY, Sergiy | D14: =Input!M9 -> Ch.Eng | E14: =Input!N9 -> Ukraine | G14: =Input!P9 -> 21788 | H14: =Input!Q9 -> Ukraine, Odessa | J14: =Input!S9 -> FU050737 | K14: =+Input!T9 -> AB640625 | L14: =Input!AA9 -> 46153 | M14: =Input!AB9 -> FRMRS | N14: 36.6 C
B15: =Input!K10 -> 5 | C15: =Input!L10 -> HONCHAR, Yurii | D15: =Input!M10 -> 2nd Eng | E15: =Input!N10 -> Ukraine | G15: =Input!P10 -> 31151 | H15: =Input!Q10 -> Ukraine | J15: =Input!S10 -> GJ014077 | K15: =+Input!T10 -> AB630373 | L15: =Input!AA10 -> 46059 | M15: =Input!AB10 -> DZBJA | N15: 36.6 C
B16: =Input!K11 -> 6 | C16: =Input!L11 -> CORCINO, Renand Aparece | D16: =Input!M11 -> A/B | E16: =Input!N11 -> Philippines | G16: =Input!P11 -> 33807 | H16: =Input!Q11 -> Inabanga, Bohol | J16: =Input!S11 -> P3970180B | K16: =+Input!T11 -> C1547533 | L16: =Input!AA11 -> 46069 | M16: =Input!AB11 -> FRMRS | N16: 36.6 C
B17: =Input!K12 -> 7 | C17: =Input!L12 -> BANEZ, John Kenneth Rebundas | D17: =Input!M12 -> O/S | E17: =Input!N12 -> Philippines | G17: =Input!P12 -> 36429 | H17: =Input!Q12 -> Malolos, Bulacan | J17: =Input!S12 -> P1370110C | K17: =+Input!T12 -> A0195751 | L17: =Input!AA12 -> 45886 | M17: =Input!AB12 -> FRLEH | N17: 36.5 C
B18: =Input!K13 -> 8 | C18: =Input!L13 -> PERNIA, James Malitao | D18: =Input!M13 -> O/S | E18: =Input!N13 -> Philippines | G18: =Input!P13 -> 36100 | H18: =Input!Q13 -> Buenavista, Marinduque | J18: =Input!S13 -> P7743571B | K18: =+Input!T13 -> C1332465 | L18: =Input!AA13 -> 46068 | M18: =Input!AB13 -> FRMRS | N18: 36.5 C
B19: =Input!K14 -> 9 | C19: =Input!L14 -> CANTOS, Philip Justin Perez | D19: =Input!M14 -> O/S | E19: =Input!N14 -> Philippines | G19: =Input!P14 -> 36743 | H19: =Input!Q14 -> Batangas City | J19: =Input!S14 -> P5075641C | K19: =+Input!T14 -> A0011575 | L19: =Input!AA14 -> 46068 | M19: =Input!AB14 -> FRMRS | N19: 36.5 C
B20: =Input!K15 -> 10 | C20: =Input!L15 -> ROMULO, Roland Bong Rosal | D20: =Input!M15 -> O/S | E20: =Input!N15 -> Philippines | G20: =Input!P15 -> 36517 | H20: =Input!Q15 -> Manila | J20: =Input!S15 -> P7652618B | K20: =+Input!T15 -> A0177653 | L20: =Input!AA15 -> 46068 | M20: =Input!AB15 -> BEANR | N20: 36.6 C
B21: =Input!K16 -> 11 | C21: =Input!L16 -> MATALUBOS, Gerald Maniapao | D21: =Input!M16 -> Wiper | E21: =Input!N16 -> Philippines | G21: =Input!P16 -> 36614 | H21: =Input!Q16 -> Navotas, Metro Manila | J21: =Input!S16 -> P0009456C | K21: =+Input!T16 -> A0154698 | L21: =Input!AA16 -> 46033 | M21: =Input!AB16 -> DZALG | N21: 36.6 C
B22: =Input!K17 -> 12 | C22: =Input!L17 -> BERNABE, Brian Malaluan | D22: =Input!M17 -> Cook | E22: =Input!N17 -> Philippines | G22: =Input!P17 -> 31894 | H22: =Input!Q17 -> Koronadal So. Cot. | J22: =Input!S17 -> P8802413B | K22: =+Input!T17 -> C1254434 | L22: =Input!AA17 -> 46063 | M22: =Input!AB17 -> ITSPE | N22: 36.6 C
B23: 13 | C23: =Input!L18 -> SISON, Jan Randell Rollo | D23: =Input!M18 -> Dcad | E23: =Input!N18 -> Philippines | G23: =Input!P18 -> 37407 | H23: =Input!Q18 -> Alaminos City | J23: =Input!S18 -> P5175257C | K23: =+Input!T18 -> A0322770 | L23: 46153 | M23: =Input!AB18 -> FRMRS | N23: 36.5 C
B25: 12. Date and signature by master, authorised agent or officer

Sheet Crew Effects
C1: IMO CREW'S EFFECTS DECLARATION
J2: Page No.
J3: 1
C4: 1. Name of ship | F4: 2. Effects which are dutiable or subject to prohibitions or restrictions (*)
C5: =Input!D2 -> HANNA
C6: 3. Nationality of Ship | F6: Cigarettes | G6: Spirirts (Ltr) | H6: Wines (Ltr) | I6: Others
C7: =Input!D4 -> Cyprus | O7: ALL CREW NAMES ARE
C8: 4. No | D8: 5. Family name, given names | E8: 6. Rank or rating | J8: 7. Signature | O8: UPDATED FROM "CREW DEP"
A9: IMO Convention on Facilitation of International Maritime Traffic | C9: 1 | D9: ='Crew Dep.'!C11 -> ZHYKHARIEV, Dmytro | E9: ='Crew Dep.'!D11 -> Master | I9: - P. E. -
C10: 2 | D10: ='Crew Dep.'!C12 -> LAURENTE, Artemio Belza | E10: ='Crew Dep.'!D12 -> Ch.Off | I10: - P. E. -
C11: 3 | D11: ='Crew Dep.'!C13 -> MAKAR, Maksym | E11: ='Crew Dep.'!D13 -> 2nd Off | I11: - P. E. -
C12: 4 | D12: ='Crew Dep.'!C14 -> ZADOROZHNY, Sergiy | E12: ='Crew Dep.'!D14 -> Ch.Eng | I12: - P. E. -
C13: 5 | D13: ='Crew Dep.'!C15 -> HONCHAR, Yurii | E13: ='Crew Dep.'!D15 -> 2nd Eng | I13: - P. E. -
C14: 6 | D14: ='Crew Dep.'!C16 -> CORCINO, Renand Aparece | E14: ='Crew Dep.'!D16 -> A/B | I14: - P. E. -
C15: 7 | D15: ='Crew Dep.'!C17 -> BANEZ, John Kenneth Rebundas | E15: ='Crew Dep.'!D17 -> O/S | I15: - P. E. -
C16: 8 | D16: ='Crew Dep.'!C18 -> PERNIA, James Malitao | E16: ='Crew Dep.'!D18 -> O/S | I16: - P. E. -
C17: 9 | D17: ='Crew Dep.'!C19 -> CANTOS, Philip Justin Perez | E17: ='Crew Dep.'!D19 -> O/S | I17: - P. E. -
C18: 10 | D18: ='Crew Dep.'!C20 -> ROMULO, Roland Bong Rosal | E18: ='Crew Dep.'!D20 -> O/S | I18: - P. E. -
C19: 11 | D19: ='Crew Dep.'!C21 -> MATALUBOS, Gerald Maniapao | E19: ='Crew Dep.'!D21 -> Wiper | I19: - P. E. -
C20: 12 | D20: ='Crew Dep.'!C22 -> BERNABE, Brian Malaluan | E20: ='Crew Dep.'!D22 -> Cook | I20: - P. E. -
C21: 13 | D21: ='Crew Dep.'!C23 -> SISON, Jan Randell Rollo | E21: ='Crew Dep.'!D23 -> Dcad | I21: - P. E. - | P21: NAMES OF PASSENGERS UPDATED FROM "PAX (A)"
C33: 8. Date and signature by master, authorised agent or officer

Sheet Ship's Stores
B1: IMO SHIP'S STORES DECLARATION
I3: Page No.
E4: X | F4: Arrival | H4: Departure | I4: 1
B5: 1. Name of ship | E5: 2. Port of arrival / departure | G5: 3. Date of arrival / departure
B6: HANNA | E6: =Input!D12 -> Napoli | G6: =Input!D8 -> 46167
B7: 4. Nationality of Ship | E7: 5. Port arrived from / Port of Destination
B8: =[1]Input!C3 -> Cyprus | E8: =Input!D14 -> Alger | G8: / | H8: =Input!D16 -> La Spezia
B9: 6. Number of Persons on board | C9: 7. Period of stay | E9: 8. Place of storage
B10: 13 | C10: 1 | E10: Provision Room
B11: 9. Name of article | D11: 10. Quantity | E11: 11. For official use
A13: IMO Convention on Facilitation of International Maritime Traffic
B14: Cigarettes | C14: Pcs | D14: 2200
B15: Cigars | C15: Pcs | D15: NIL
B16: Tobacco | C16: grm | D16: NIL
B17: Spirits 35-42 % | C17: 1 ltr | D17: NIL
B22: Fortified wine 18% | C22: LTR | D22: NIL
B23: Wine 10-13% | C23: LTR | D23: NIL
B24: Liqueurs | C24: 0,75 ltr | D24: NIL
B25: Beer | C25: Ltr | D25: 16
B28: Arms & Ammunition | D28: NIL
A39: IMO FAL
A40: Form 3
B41: 12. Date and signature by master, authorised agent or officer
E47: PT(August 2003)

Sheet PAX (A)
B1: IMO PASSENGER LIST
J3: Page No.
E4: x | F4: Arrival | I4: Departure | J4: 1
B5: 1. Name of ship | E5: 2. Port of arrival / departure | H5: 3. Date of arrival / departure
B6: =Input!D2 -> HANNA | E6: =Input!D12 -> Napoli | H6: =Input!D8 -> 46167
B7: 4. Nationality of Ship | E7: 5. Port arrived from / Sailing to | J7: 6. Nature und No. of identity documents
B8: =Input!D4 -> Cyprus | E8: =Input!D14 -> Alger | H8: / | I8: =Input!D16 -> La Spezia
B9: 7. No. | C9: 8. Family names, given names | D9: 9. Rank or rating | E9: 10. Nationality | G9: 11. Date and place of birth | J9: Identity Card/
J10: Passport
A11: IMO Convention on Facilitation of International Maritime Traffic | C11: NO PASSENGERS ON BOARD
B35: 12. Date and signature by master, authorised agent or officer
E44: PT(August 2003)

Sheet PAX (D)
B1: IMO PASSENGER LIST
J3: Page No.
F4: Arrival | H4: x | I4: Departure | J4: 1
B5: 1. Name of ship | E5: 2. Port of arrival / departure | H5: 3. Date of arrival / departure
B6: =Input!D2 -> HANNA | E6: =Input!D12 -> Napoli | H6: =Input!D10 -> 46168
B7: 4. Nationality of Ship | E7: 5. Port of destination | J7: 5. Nature und No. of identity documents
B8: =Input!D4 -> Cyprus | E8: =Input!D16 -> La Spezia
B9: 7. No. | C9: 8. Family names, given names | D9: 9. Rank or rating | E9: 10. Nationality | G9: 11. Date and place of birth | J9: Identity Card/
J10: Passport
A11: IMO Convention on Facilitation of International Maritime Traffic
B12: 1 | C12: BRENNER, Dirk Oliver | D12: Technician | E12: Germany | G12: 27965 | I12: Bremerhaven | J12: C26H57RGX
B13: 2 | C13: EHLER, Jan | D13: Technician | E13: Germany | G13: 36878 | I13: Heide | J13: C1FHVNW65
B35: 12. Date and signature by master, authorised agent or officer
E44: PT(August 2003)

Sheet NIL List
A3: NIL LIST
A6: Vessel: | C6: =Input!D2 -> HANNA | F6: Port: | G6: =Input!D12 -> Napoli
A7: Port of registry: | C7: =Input!H4 -> Limassol | F7: Date: | G7: =Input!D8 -> 46167
B11: THERE ARE NO PASSENGERS ON BOARD.
B13: THERE ARE NO ANIMALS AND BIRDS ON BOARD.
B15: THERE ARE NO ARMS AND AMMUNITIONS ON BOARD.
B17: THERE ARE NO STOWAWAYS ON BOARD.
E36: Master | G36: =Input!L6 -> ZHYKHARIEV, Dmytro

Sheet Ship money
A3: Ship money cash declaration
A6: Vessel: | C6: =Input!D2 -> HANNA | F6: Port: | G6: =Input!D12 -> Napoli
A7: Port of registry: | C7: =Input!H4 -> Limassol | F7: Date: | G7: =Input!D8 -> 46167
B12: 2800
B14: 6300
E29: Master | G29: =Input!L6 -> ZHYKHARIEV, Dmytro

Sheet MDH
A1: MARITIME DECLARATION OF HEALTH
B4: Port of | C4: ALGER | F4: Date | G4: =Input!D8 -> 46167 | H4: Time | L4: <=== correct time
B5: Name of Vessel | C5: =Input!D2 -> HANNA | F5: From | G5: =Input!D14 -> Alger | H5: To | I5: =Input!D16 -> La Spezia
B6: Nationality | C6: =Input!D4 -> Cyprus | F6: Master's Name | G6: =Input!$L$6 -> ZHYKHARIEV, Dmytro
B7: Net Registered Tonnage | D7: 6006 | F7: Agent or Owner | G7: CMA-CGM | L7: <=== correct agent
B9: Ship's Sanitation Certificate | D9: Issued at | E9: MARSEILLE | F9: Dated | G9: 46021
F11: Water test: | G11: MARSEILLE 05.01.2026
C13: First Class | D13: nil | F13: No. of Crew | G13: 13
B14: No. of | C14: Cabin Class | D14: nil | L14: <=== correct pax
B15: Passengers | C15: Tourist Class | D15: nil
C16: Third Class | D16: nil
B17: List of Ports of call from commencement of voyage with dates of departure | G17: DEPARTURE | H17: PORT
B19: 1 | C19: ='ISPS (POC Company Form)'!C13 -> ALGER | G19: ='ISPS (POC Company Form)'!H13 -> 46166 | H19: ='ISPS (POC Company Form)'!E13 -> DZALG
B20: 2 | C20: ='ISPS (POC Company Form)'!C14 -> MARSEILLE | G20: ='ISPS (POC Company Form)'!H14 -> 46154 | H20: ='ISPS (POC Company Form)'!E14 -> FRMRS
B21: 3 | C21: ='ISPS (POC Company Form)'!C15 -> LA SPEZIA | G21: ='ISPS (POC Company Form)'!H15 -> 46152 | H21: ='ISPS (POC Company Form)'!E15 -> ITSPE
B22: 4 | C22: ='ISPS (POC Company Form)'!C16 -> GENOA | G22: ='ISPS (POC Company Form)'!H16 -> 46151 | H22: ='ISPS (POC Company Form)'!E16 -> ITGOA
B23: 5 | C23: ='ISPS (POC Company Form)'!C17 -> SALERNO | G23: ='ISPS (POC Company Form)'!H17 -> 46149 | H23: ='ISPS (POC Company Form)'!E17 -> ITSAL
B24: 6 | C24: ='ISPS (POC Company Form)'!C18 -> NAPOLI | G24: ='ISPS (POC Company Form)'!H18 -> 46144 | H24: ='ISPS (POC Company Form)'!E18 -> ITNAP
B25: 7 | C25: ='ISPS (POC Company Form)'!C19 -> ALGER | G25: ='ISPS (POC Company Form)'!H19 -> 46140 | H25: ='ISPS (POC Company Form)'!E19 -> DZALG
B26: 8 | C26: ='ISPS (POC Company Form)'!C20 -> MARSEILLE | G26: ='ISPS (POC Company Form)'!H20 -> 46133 | H26: ='ISPS (POC Company Form)'!E20 -> FRMRS
B27: 9 | C27: ='ISPS (POC Company Form)'!C21 -> GENOA | G27: ='ISPS (POC Company Form)'!H21 -> 46129 | H27: ='ISPS (POC Company Form)'!E21 -> ITGOA
B28: 10 | C28: ='ISPS (POC Company Form)'!C22 -> LA SPEZIA | G28: ='ISPS (POC Company Form)'!H22 -> 46129 | H28: ='ISPS (POC Company Form)'!E22 -> ITSPE
E30: Health Questions
B31: 1. Has there been on board during the voyage any case or suspected case of plague | I31: No
B32: cholera, yellow fever, typhus fever, or smallpox? Give particulars in the schedule
B34: Has plague occured or been suspected among the rats or mice on board during the voyage | I34: No
B35: or has there been an unusual mortality rate among them?
B37: 3. Has any person died on board during the voyage other than as a result of an accident? | I37: No
B38: Give particulars in the schedule.
B40: 4. Is there on board or has there been during the voyage any case of illnes | I40: No
B41: which You suspect to be of an infectious nature? Give particulars in the schedule
I42: No
B43: 5. Is there any sick person on board now? Give particulars in the schedule.
B45: Note: | C45: In the absence of a Surgeon, the master should regard the following symptoms
C46: as grounds for suspecting the existence of infectious disease:
C47: fever accompanied by prostation persisting fpr several days, or attended with
C48: glandular swelling; or any acute skin rash or erruption with or without fever;
C49: severe diarrhoea with symptoms of collapse; jaindice accompanied by fever.
I50: No
B51: 6. Are You aware of any other condition on board which may lead to infection or the spread
...

Sheet Narcotic List
B2: NARCOTICS LIST
I3: Page No. 1
B4: 1. Name of ship | E4: Port of arrival | G4: Date:
B5: =Input!D2 -> HANNA | E5: =Input!D12 -> Napoli | G5: =Input!D8 -> 46167
B6: 4. Nationality of Ship | E6: Port Arrived from | G6: Port of Destination
B7: =Input!D4 -> Cyprus | E7: =Input!D14 -> Alger | G7: =Input!D16 -> La Spezia
B8: No. | C8: Medicines Name | D8: Quantity | E8: Units | F8: Total Quantity | G8: Expiration Date | H8: Control no. | I8: Place of Storage
B10: =[2]Input!J12 -> 1 | C10: Codeine phosphate 30mg tablets | D10: 3 | E10: 20 tabs. per box | F10: 60 tabs. | G10: 10/2026 | H10: Nr.3.b.1 | I10: Master's Safe
B11: =[2]Input!J13 -> 2 | C11: Tramadol 100mg/2ml injection | D11: 2 | E11: 20 amps. per box | F11: 40 amps. | G11: 01/2029 | H11: Nr.3.b.2 | I11: Master's Safe
B12: 3 | C12: Diazepam injection 5mg/1ml, 2ml | D12: 1 | E12: 5 amps. per box | F12: 5 amps. | G12: 08/2026 | H12: Nr.4.a.1 | I12: Master's Safe
B13: 4 | C13: Diazepam rectal dispenser 10mg/2.5ml | D13: 2 | E13: 5 amps. per box | F13: 10 amps. | G13: 04/2027 | H13: Nr.4.d.0 | I13: Master's Safe
B18: Date and signature by master, authorised agent or officer Capt. Zhukhariev, Dmytro

Sheet Crew Money
C1: CREW MONEY LIST
J2: Page No.
J3: 1
C4: 1. Name of ship | F4: 2. Currency
C5: =Input!D2 -> HANNA
C6: 3. Nationality of Ship | F6: USD | H6: EURO | I6: Others
C7: =Input!D4 -> Cyprus
C8: 4. No | D8: 5. Family name, given names | E8: 6. Rank or rating | J8: 7. Signature
A9: IMO Convention on Facilitation of International Maritime Traffic | C9: 1 | D9: ='Crew Arr.'!C11 -> ZHYKHARIEV, Dmytro | E9: ='Crew Arr.'!D11 -> Master
C10: 2 | D10: ='Crew Arr.'!C12 -> LAURENTE, Artemio Belza | E10: ='Crew Arr.'!D12 -> Ch.Off
C11: 3 | D11: ='Crew Arr.'!C13 -> MAKAR, Maksym | E11: ='Crew Arr.'!D13 -> 2nd Off
C12: 4 | D12: ='Crew Arr.'!C14 -> ZADOROZHNY, Sergiy | E12: ='Crew Arr.'!D14 -> Ch.Eng
C13: 5 | D13: ='Crew Arr.'!C15 -> HONCHAR, Yurii | E13: ='Crew Arr.'!D15 -> 2nd Eng
C14: 6 | D14: ='Crew Arr.'!C16 -> CORCINO, Renand Aparece | E14: ='Crew Arr.'!D16 -> A/B
C15: 7 | D15: ='Crew Arr.'!C17 -> BANEZ, John Kenneth Rebundas | E15: ='Crew Arr.'!D17 -> O/S
C16: 8 | D16: ='Crew Arr.'!C18 -> PERNIA, James Malitao | E16: ='Crew Arr.'!D18 -> O/S
C17: 9 | D17: ='Crew Arr.'!C19 -> CANTOS, Philip Justin Perez | E17: O/S
C18: 10 | D18: ='Crew Arr.'!C20 -> ROMULO, Roland Bong Rosal | E18: ='Crew Arr.'!D20 -> O/S
C19: 11 | D19: ='Crew Arr.'!C21 -> MATALUBOS, Gerald Maniapao | E19: ='Crew Arr.'!D21 -> Wiper
C20: 12 | D20: ='Crew Arr.'!C22 -> BERNABE, Brian Malaluan | E20: ='Crew Arr.'!D22 -> Cook
C21: 13 | D21: ='Crew Arr.'!C23 -> SISON, Jan Randell Rollo | E21: ='Crew Arr.'!D23 -> Dcad
C33: 8. Date and signature by master, authorised agent or officer
D44: (*) eg wines, sprits, cigarettes, tobacco, etc.

Sheet Cash Adv.
B1: Payroll of Christmas Bonus from the Owners
B3: Vessel: | C3: =Input!D2 -> HANNA | E3: Received | K3: Signature
B4: Date: | C4: 46015
B5: No. | C5: Crew | D5: Rank | E5: USD | H5: EUR
B6: =Input!K6 -> 1 | C6: =+Input!L6 -> ZHYKHARIEV, Dmytro | D6: =Input!M6 -> Master
B7: =Input!K7 -> 2 | C7: =+Input!L7 -> LAURENTE, Artemio Belza | D7: =Input!M7 -> Ch.Off
B8: =Input!K8 -> 3 | C8: =+Input!L8 -> MAKAR, Maksym | D8: =Input!M8 -> 2nd Off
B9: =Input!K9 -> 4 | C9: =+Input!L9 -> ZADOROZHNY, Sergiy | D9: =Input!M9 -> Ch.Eng
B10: =Input!K10 -> 5 | C10: =+Input!L10 -> HONCHAR, Yurii | D10: =Input!M10 -> 2nd Eng
B11: =Input!K11 -> 6 | C11: =+Input!L11 -> CORCINO, Renand Aparece | D11: =Input!M11 -> A/B
B12: =Input!K12 -> 7 | C12: =+Input!L12 -> BANEZ, John Kenneth Rebundas | D12: =Input!M12 -> O/S
B13: =Input!K13 -> 8 | C13: =+Input!L13 -> PERNIA, James Malitao | D13: =Input!M13 -> O/S
B14: =Input!K14 -> 9 | C14: =+Input!L14 -> CANTOS, Philip Justin Perez | D14: =Input!M14 -> O/S
B15: =Input!K15 -> 10 | C15: =+Input!L15 -> ROMULO, Roland Bong Rosal | D15: =Input!M15 -> O/S
B16: =Input!K16 -> 11 | C16: =+Input!L16 -> MATALUBOS, Gerald Maniapao | D16: =Input!M16 -> Wiper
B17: =Input!K17 -> 12 | C17: =+Input!L17 -> BERNABE, Brian Malaluan | D17: =Input!M17 -> Cook
B18: =Input!K18 -> 13 | C18: =+Input!L18 -> SISON, Jan Randell Rollo | D18: =Input!M18 -> Dcad
B19: TOTAL:
E23: Master | I23: / Zhukhariev, Dmytro /
I25: 46015

Sheet Smokers
A2: List of Smokers
A4: (Name of Shipping Line / Agent etc.)
B5: =Input!D18 -> CMA CGM
A6: 1.Name of Ship | D6: Call Sign | E6: 2.Port of Arrival | J6: 3.Date
A7: =Input!D2 -> HANNA | D7: =Input!H2 -> 5BGV2 | E7: =+Input!D12 -> Napoli | J7: =Input!D8 -> 46167
A8: 4.Nationality of Ship | D8: 5. Homeport | E8: 6.Port arrived from
A9: =Input!D4 -> Cyprus | D9: =Input!H4 -> Limassol | E9: =Input!D14 -> Alger
A10: 8.No. 9. Family Name, given Names | D10: "I am a smoker" please indicate "YES" or "NO" | G10: If smoking please indicate approx. consumption per day (pieces of cigarettes) | J10: Signature
A12: =Input!K6 -> 1 | B12: =Input!L6 -> ZHYKHARIEV, Dmytro
A13: =Input!K7 -> 2 | B13: =Input!L7 -> LAURENTE, Artemio Belza
A14: =Input!K8 -> 3 | B14: =Input!L8 -> MAKAR, Maksym
A15: =Input!K9 -> 4 | B15: =Input!L9 -> ZADOROZHNY, Sergiy
A16: =Input!K10 -> 5 | B16: =Input!L10 -> HONCHAR, Yurii
A17: =Input!K11 -> 6 | B17: =Input!L11 -> CORCINO, Renand Aparece
A18: =Input!K12 -> 7 | B18: =Input!L12 -> BANEZ, John Kenneth Rebundas
A19: =Input!K13 -> 8 | B19: =Input!L13 -> PERNIA, James Malitao
A20: =Input!K14 -> 9 | B20: =Input!L14 -> CANTOS, Philip Justin Perez
A21: =Input!K15 -> 10 | B21: =Input!L15 -> ROMULO, Roland Bong Rosal
A22: =Input!K16 -> 11 | B22: =Input!L16 -> MATALUBOS, Gerald Maniapao
A23: =Input!K17 -> 12 | B23: =Input!L17 -> BERNABE, Brian Malaluan
A24: =Input!K18 -> 13 | B24: =Input!L18 -> SISON, Jan Randell Rollo
E30: Master: | G30: =Input!L6 -> ZHYKHARIEV, Dmytro

Sheet Vaccination
A2: Vaccination List
A4: (Name of Shipping Line / Agent etc.) | J4: Voyage No.
B5: =Input!D18 -> CMA CGM
A6: 1.Name of Ship | D6: Call Sign | E6: 2.Port of Arrival | J6: 3.Date of Arrival
A7: =Input!D2 -> HANNA | D7: =Input!H2 -> 5BGV2 | E7: =Input!D12 -> Napoli | J7: =Input!D8 -> 46167
A8: 4.Nationality of Ship | D8: 5. Homeport | E8: 6.Port arrived from | J8: 7.Date of Departure
A9: =Input!D4 -> Cyprus | D9: =Input!H4 -> Limassol | E9: =Input!D14 -> Alger | J9: =Input!D10 -> 46168
A10: 8.No. 9. Family Name, given Names | D10: 10. Yellow Fever | E10: 11. Cholera | F10: 12. Typhus | G10: 13. Hepatitis A | H10: 14.Polio | I10: 15. Diphteria | J10: 15. Tetanus
A12: =Input!K6 -> 1 | B12: =Input!L6 -> ZHYKHARIEV, Dmytro
A13: =Input!K7 -> 2 | B13: =Input!L7 -> LAURENTE, Artemio Belza
A14: =Input!K8 -> 3 | B14: =Input!L8 -> MAKAR, Maksym | L14: ONLY stand by in EGYPT
A15: =Input!K9 -> 4 | B15: =Input!L9 -> ZADOROZHNY, Sergiy
A16: =Input!K10 -> 5 | B16: =Input!L10 -> HONCHAR, Yurii
A17: =Input!K11 -> 6 | B17: =Input!L11 -> CORCINO, Renand Aparece
A18: =Input!K12 -> 7 | B18: =Input!L12 -> BANEZ, John Kenneth Rebundas
A19: =Input!K13 -> 8 | B19: =Input!L13 -> PERNIA, James Malitao
A20: =Input!K14 -> 9 | B20: =Input!L14 -> CANTOS, Philip Justin Perez
A21: =Input!K15 -> 10 | B21: =Input!L15 -> ROMULO, Roland Bong Rosal
A22: =Input!K16 -> 11 | B22: =Input!L16 -> MATALUBOS, Gerald Maniapao
A23: =Input!K17 -> 12 | B23: =Input!L17 -> BERNABE, Brian Malaluan
A24: =Input!K18 -> 13 | B24: =Input!L18 -> SISON, Jan Randell Rollo
H33: ___________________
H34: Master

Sheet Crew Contact Nos.
A1: CREW CONTACT INFORMATION
A3: =Input!D2 -> HANNA | D3: Telephone / Email
A5: =Input!D4 -> Cyprus
A7: No. | B7: Family Names, Given Names | C7: Rank or Rating | D7: Nationality | E7: National Phone No. | F7: France/Europe Phone No. | G7: WhatsApp/Viber/Telegram | H7: FB Messenger | I7: Email Address
A9: =Input!K6 -> 1 | B9: =Input!L6 -> ZHYKHARIEV, Dmytro | C9: =Input!M6 -> Master | D9: =Input!N6 -> Ukraine
A10: =Input!K7 -> 2 | B10: =Input!L7 -> LAURENTE, Artemio Belza | C10: =Input!M7 -> Ch.Off | D10: =Input!N7 -> Philippines
A11: =Input!K8 -> 3 | B11: =Input!L8 -> MAKAR, Maksym | C11: =Input!M8 -> 2nd Off | D11: =Input!N8 -> Ukraine
A12: =Input!K9 -> 4 | B12: =Input!L9 -> ZADOROZHNY, Sergiy | C12: =Input!M9 -> Ch.Eng | D12: =Input!N9 -> Ukraine
A13: =Input!K10 -> 5 | B13: =Input!L10 -> HONCHAR, Yurii | C13: =Input!M10 -> 2nd Eng | D13: =Input!N10 -> Ukraine
A14: =Input!K11 -> 6 | B14: =Input!L11 -> CORCINO, Renand Aparece | C14: =Input!M11 -> A/B | D14: =Input!N11 -> Philippines
A15: =Input!K12 -> 7 | B15: =Input!L12 -> BANEZ, John Kenneth Rebundas | C15: =Input!M12 -> O/S | D15: =Input!N12 -> Philippines
A16: =Input!K13 -> 8 | B16: =Input!L13 -> PERNIA, James Malitao | C16: =Input!M13 -> O/S | D16: =Input!N13 -> Philippines
A17: =Input!K14 -> 9 | B17: =Input!L14 -> CANTOS, Philip Justin Perez | C17: =Input!M14 -> O/S | D17: =Input!N14 -> Philippines
A18: =Input!K15 -> 10 | B18: =Input!L15 -> ROMULO, Roland Bong Rosal | C18: =Input!M15 -> O/S | D18: =Input!N15 -> Philippines
A19: =Input!K16 -> 11 | B19: =Input!L16 -> MATALUBOS, Gerald Maniapao | C19: =Input!M16 -> Wiper | D19: =Input!N16 -> Philippines
A20: =Input!K17 -> 12 | B20: =Input!L17 -> BERNABE, Brian Malaluan | C20: =Input!M17 -> Cook | D20: =Input!N17 -> Philippines
A21: =Input!K18 -> 13 | B21: =Input!L18 -> SISON, Jan Randell Rollo | C21: =Input!M18 -> Dcad | D21: =Input!N18 -> Philippines
A22: **CAPTAIN STANDING ORDER!!! All Crew, must inform duty officer and update their contact details before going ashore.
